Workbook

Sheet STOCK
A1: Material | B1: MaterialDescription | C1: MODEL | D1: STOCK | E1: MVMT | F1: USED SPARES | G1: PRICE | H1: ISSE GO DOWN | I1: SEP | J1: SHRM | K1: HOME
A2: 40007327 | B2: MAKTEC SWITCH 651527-9 MT921 | C2: 651527-9 | D2: 1 | E2: 35 | F2: 1 | G2: 35 | H2: - | I2: 15 | J2: MA224 | K2: AA91 | M2: ART | N2: PART | O2: QTY | P2: STCK | Q2: MAR | R2: APR | S2: AIR | T2: PRICE | U2: TOTAL | V2: SR | W2: HM
A3: 40010351 | B3: MAKTEC SWITCH 650545-4 MT240 | C3: 650545-4 | D3: 6 | E3: 8 | F3: - | G3: 37 | H3: - | I3: 2 | J3: GE04 | K3: - | M3: 10017943 | N3: UC012gz | O3: 2 | P3: 1 | Q3: 2 | R3: - | S3: #REF! | T3: 9370 | U3: 18740 | V3: - | W3: HT10 | X3: s002
A4: 40007189 | B4: MAKTEC SPRING PIN 3-6 258002-2 | C4: 258002-2 | D4: 8 | E4: 1 | F4: - | G4: 1 | H4: - | J4: MA175 | K4: - | M4: 10019051 | N4: LW1401 | O4: 1 | P4: 2 | Q4: 80 | R4: - | S4: #REF! | T4: 5315 | U4: 5315 | V4: OFFICE | W4: HT11 | X4: s002
A5: 40007052 | B5: MAKTEC H.GEAR 226586-8/226554-1 MT811 | C5: 226586-8 | D5: 25 | E5: 3 | F5: - | G5: 52 | H5: - | J5: CK03 | K5: - | M5: 10018875 | N5: M2401B | O5: 2 | P5: 8 | Q5: - | R5: - | S5: #REF! | T5: 3695 | U5: 7390 | V5: OFFICE | W5: HT11 | X5: s002
A6: 10019955 | B6: MAKTEC DRILL CHUCK 1/2' MT811 763161-4 | C6: 763161-4 | D6: 22 | E6: 163 | F6: 2 | G6: 97 | H6: - | I6: 30 | J6: CHUCK | K6: - | M6: - | O6: 1 | P6: - | Q6: - | R6: - | S6: #REF! | T6: - | U6: - | V6: - | W6: -
A7: 10019954 | B7: MAKTEC CH.KEY FOR MT650 763442-6 | C7: 763442-6 | D7: 10 | E7: 14 | F7: - | G7: 16 | H7: - | J7: 65(2) | K7: - | M7: - | O7: 1 | P7: - | Q7: - | R7: - | S7: #REF! | T7: - | U7: - | V7: - | W7: -
A8: 40007058 | B8: MAKTEC BTTRY CHRGR DC1251 193941-8 MT066 | C8: 193941-8 | D8: 1 | E8: 0 | F8: - | G8: 673 | H8: - | J8: 85 | K8: - | M8: - | O8: 1 | P8: - | Q8: - | R8: - | S8: #REF! | T8: - | U8: - | V8: - | W8: -
A9: 40007188 | B9: MAKTEC BLADE CAMP 325601-6 MT430 | C9: 325601-6 | D9: 19 | E9: 2 | F9: - | G9: 41 | H9: - | J9: MA19 | K9: - | M9: - | O9: 2 | P9: - | Q9: - | R9: - | S9: #REF! | T9: - | U9: - | V9: - | W9: -
A10: 40007042 | B10: MAKTEC BATTERY 9050 MT062 193710-7(9.6V) | C10: 193710-7 | D10: 6 | E10: 0 | F10: - | G10: 627 | H10: - | J10: 85 | K10: - | M10: - | O10: 2 | P10: - | Q10: - | R10: - | S10: #REF! | T10: - | U10: 190 | V10: - | W10: -
A11: 40007051 | B11: MAKTEC BATTERY 7050 SET 193959-9 MT066 | C11: 193959-9 | D11: 4 | E11: 1 | F11: - | G11: 347 | H11: - | J11: 86 | K11: - | M11: - | O11: 2 | P11: - | Q11: - | R11: - | S11: #REF! | T11: - | U11: - | V11: - | W11: -
A12: 40007750 | B12: MAKTEC ARMATURE MT360 516909-1 | C12: 516909-1 | D12: 3 | E12: 0 | F12: - | G12: 586 | H12: - | J12: 23 | K12: - | M12: - | O12: 2 | P12: - | Q12: - | R12: - | S12: #REF! | T12: - | U12: - | V12: - | W12: -
A13: 40007475 | B13: MAKTEC ARMATURE JM23000100 MT230 | C13: JM23000100 | D13: 12 | E13: 1 | F13: - | G13: 981 | H13: - | J13: 2 | K13: 93 | M13: - | O13: 1 | P13: - | Q13: - | R13: - | S13: #REF! | T13: - | U13: - | V13: - | W13: -
A14: 40007743 | B14: MAKTEC ARMATURE ASS'Y 517409-4 MT950 | C14: 517409-4 | D14: 7 | E14: 0 | F14: - | G14: 186 | H14: - | J14: - | K14: 98 | M14: - | O14: 1 | P14: - | Q14: - | R14: - | S14: #REF! | T14: - | U14: - | V14: - | W14: -
A15: 40007499 | B15: MAKTEC ARMATURE 517479-3 MT603 | C15: 517479-3 | D15: 10 | E15: 0 | F15: - | G15: 225 | H15: - | J15: J1 | K15: 98 | M15: - | O15: 1 | P15: - | Q15: - | R15: - | S15: #REF! | T15: - | U15: - | V15: - | W15: -
A16: 40007480 | B16: MAKTEC ARMATURE 517454-9 MT953 | C16: 517454-9 | D16: 7 | E16: 3 | F16: - | G16: 266 | H16: - | J16: C7 | K16: 60 | M16: - | O16: 1 | P16: - | Q16: - | R16: - | S16: #REF! | T16: - | U16: - | V16: - | W16: -
A17: 40007472 | B17: MAKTEC ARMATURE 513549-6 MT580/MT560 | C17: 513549-6 | D17: 5 | E17: 41 | F17: 1 | G17: 340 | H17: - | I17: 7 | J17: 6 | K17: 18 | M17: - | P17: - | Q17: - | R17: - | S17: #REF! | T17: - | U17: - | V17: - | W17: -
A18: 40006222 | B18: MAKTA BEARING BOX 319351-3 GA7060 | C18: 319351-3 | D18: 1 | E18: 0 | F18: - | G18: 41 | H18: - | J18: - | K18: 75 | M18: - | P18: - | Q18: - | R18: - | S18: #REF! | T18: - | W18: -
A19: 40006144 | B19: MAKITATRIGGERVALVE SET B0500-0181(AF301) | C19: B0500-0181 | D19: 10 | E19: 0 | F19: - | G19: 19 | H19: - | J19: ZI16 | K19: - | M19: - | P19: - | Q19: - | R19: - | S19: #REF! | T19: -
A20: 40005533 | B20: MAKITASPIRAL BEVEL GEAR 37 227627-3 | C20: 227627-3 | D20: 5 | E20: 4 | F20: - | G20: 104 | H20: - | J20: HM03 | K20: - | M20: - | P20: - | Q20: - | R20: - | S20: #REF! | T20: -
A21: 40007621 | B21: MAKITAPAD COMPLETE FOR BO3700 140441-9 | C21: 140441-9 | D21: 67 | E21: 349 | F21: 4 | G21: 34 | H21: - | I21: 40 | J21: H30 | K21: - | M21: - | P21: - | Q21: - | R21: - | S21: #REF! | T21: -
A22: 10019539 | B22: MAKITADRESSINGSTONE100X16X10 9803A-24642 | C22: A-24642 | D22: 3 | E22: 2 | F22: - | G22: 110 | H22: - | J22: 80 | K22: - | M22: - | P22: - | Q22: - | R22: - | S22: #REF! | T22: -
A23: 40007493 | B23: MAKITAARMATURE629827-5 629927-5 8414DWAE | C23: 629827-5 | D23: 5 | E23: 1 | F23: - | G23: 367 | H23: - | J23: F20 | K23: 72 | M23: - | P23: - | Q23: - | R23: - | S23: #REF! | T23: -
A24: 40007583 | B24: MAKITA ZEROL LEVEL GERA 13 / 227412-4 | C24: 227412-4 | D24: 2 | E24: 0 | F24: - | G24: 224 | H24: - | J24: ZN06 | K24: - | M24: - | P24: - | Q24: - | R24: - | S24: #REF! | T24: -
A25: 40007582 | B25: MAKITA ZEROL LEVEL GEAR 19 / 227411-6 | C25: 227411-6 | D25: 2 | E25: 0 | F25: - | G25: 376 | H25: - | J25: CD07 | K25: - | M25: - | P25: - | Q25: - | R25: - | S25: #REF! | T25: -
A26: 40005361 | B26: MAKITA YOKE UNIT FOR DTD130 632U16-9 | C26: 632U16-9 | D26: 6 | E26: 8 | F26: - | G26: 122 | H26: - | J26: D8 | K26: -
A27: 40005785 | B27: MAKITA YOKE UNIT FOR BPB180 638420-4 | C27: 638420-4 | D27: 7 | E27: 0 | F27: - | G27: 321 | H27: - | J27: A6 | K27: -
A28: 40005933 | B28: MAKITA YOKE UNIT FOR BDF441 632J71-5 | C28: 632J71-5 | D28: 6 | E28: 4 | F28: - | G28: 175 | H28: - | J28: B17 | K28: -
A29: 40006123 | B29: MAKITA YOKE UNIT 638989-8 (BHP458) | C29: 638989-8 | D29: 3 | E29: 6 | F29: - | G29: 207 | H29: - | J29: B26 | K29: -
A30: 40006862 | B30: MAKITA YOKE UNIT 638627-2 | C30: 638627-2 | D30: 4 | E30: 0 | F30: - | G30: 365 | H30: - | J30: - | K30: 48
A31: 40006440 | B31: MAKITA YOKE UNIT 632J70-7 DHP482 | C31: 632J70-7 | D31: 98 | E31: 204 | F31: 7 | G31: 153 | H31: - | J31: WA64 | K31: -
A32: 40006063 | B32: MAKITA YOKE UNIT 638423-8 BHP450 | C32: 638423-8 | D32: 4 | E32: 1 | F32: - | G32: 119 | H32: - | J32: - | K32: AB23
A33: 40007738 | B33: MAKITA Y RING 45 213575-2 HM1305 | C33: 213575-2 | D33: 7 | E33: 0 | F33: - | G33: 46 | H33: - | J33: MA06 | K33: -
A34: 40006705 | B34: MAKITA Y RING 34 213494-2 | C34: 213494-2 | D34: 8 | E34: 6 | F34: - | G34: 46 | H34: - | J34: WA49 | K34: -
A35: 40007386 | B35: MAKITA Y RING 34 FOR HM1302 213477-2 | C35: 213477-2 | D35: 3 | E35: 1 | F35: - | G35: 56 | H35: - | J35: MA231 | K35: -
A36: 40010403 | B36: MAKITA X-RING 21 FOR HM1214C 213980-3 | C36: 213980-3 | D36: 4 | E36: 0 | F36: - | G36: 85 | H36: - | J36: MA254 | K36: -
A37: 40007734 | B37: MAKITA X RING 28 FOR HM0810 213428-5 | C37: 213428-5 | D37: 2 | E37: 5 | F37: - | G37: 69 | H37: - | I37: 2 | J37: ZO15 | K37: -
A38: 10044115 | B38: MAKITA WRENCH 22 FOR 3620 781011-1 | C38: 781011-1 | D38: 3 | E38: 1 | F38: - | G38: 30 | H38: - | J38: 48 | K38: -
A39: 10044116 | B39: MAKITA WRENCH 13 FOR PM001G 781039-9 | C39: 781039-9 | D39: 4 | E39: 1 | F39: - | G39: 19 | H39: - | J39: 48 | K39: -
A40: 40007374 | B40: MAKITA WORM UC4000 021245040 | C40: 021245040 | D40: 76 | E40: 0 | F40: - | G40: 8 | H40: - | J40: HH04 | K40: -
...

Sheet Sheet5
C3: Material | D3: MaterialDescription | E3: MODEL | G3: STOCK | H3: SR | I3: HM | N3: SHOP 137 S305 4430036854 | O3: QTY | P3: S002 | Q3: D004 | S3: 1 | T3: 1
C4: 10018620 | D4: MAKITA WIRE CUP BRUSH M10X1.50 D-24066 | E4: D-24066 | F4: SCM190202 | G4: 5 | L4: 30 | M4: 10019054 | N4: MAKITA DC DRIVER DRILL DDF482RTE 18V | P4: 15 | Q4: 16 | S4: 2 | T4: 5
C5: 10018202 | D5: MAKITA WIDE RANGE NOZZLE SET 191X19-5 | E5: 191X19-5 | F5: SCM190202 | G5: 1 | L5: 40 | M5: 10018720 | N5: MAKITA HAMMER DRILL 18V BL13MM DHP486RTE | O5: 3 | P5: 10 | Q5: 28 | S5: 3 | T5: 2
C6: 10048674 | D6: MAKITA USB ADAPTER XGT 40V ADP001G | E6: ADP001G | F6: SCM190202 | G6: 1 | L6: 80 | M6: 10013659 | N6: MAKITA DRILL DP4700 (13MM) 1/2" | O6: 5 | P6: 60 | Q6: 70 | S6: 4 | T6: 4
C7: 10018262 | D7: MAKITA TRIPOD DML811/ ML003G GM00002073 | E7: GM00002073 | F7: SCM190202 | G7: 1 | L7: 10 | M7: 10019274 | N7: MAKITA DRILL BIT WOOD D-07185 (12MM) | P7: 20 | S7: 5 | T7: 2
C8: 10050325 | D8: MAKITA TOOL BAG BLACK 60X20CM 199901-8 | E8: 199901-8 | F8: SCM190202 | G8: 1 | L8: 20 | M8: 10019272 | N8: MAKITA DRILL BIT WOOD D-07179 (10MM) | P8: 10 | S8: 6 | T8: 5
C9: 10018797 | D9: MAKITA TIE WIRE SET DTR181 199137-9 | E9: 199137-9 | F9: SCM190202 | G9: 3 | L9: 50 | M9: 10018680 | N9: MAKITA METAL DRILL BIT 19PCS D-67583 | P9: 9 | S9: 7 | T9: 20
C10: 40012067 | D10: MAKITA THIN WASHER 6 FOR 9741 253308-3 | E10: 253308-3 | F10: SCM200112 | G10: 1 | L10: 60 | M10: 10018115 | N10: MAKITA C-LESS HAMMER DRILL DHP484RTE | P10: 14 | S10: 8 | T10: 20
C11: 10018452 | D11: MAKITA THIN CUT-OFF WHEEL 6" E-13742 | E11: E-13742 | F11: SCM190103 | G11: 20 | L11: 70 | M11: 10018110 | N11: MAKITA C-LESS HMER DRILL HP332DSAE 12V | P11: 14 | S11: 9 | T11: 20
C12: 10049263 | D12: MAKITA TCT SAWBLADE EFF 260X60T B-67430 | E12: B-67430 | F12: SCM190101 | G12: 1 | S12: 10 | T12: 20
C13: 10019301 | D13: MAKITA TCT SAWBLADE 792299-8 50T 85MM | E13: 792299-8 | F13: SCM190101 | G13: 1 | N13: SHOP 137 S305 4430037210 | S13: 11 | T13: 2
C14: 10019339 | D14: MAKITA TCT SAW BLADE METAL B-23117 136MM | E14: B-23117 | F14: SCM190101 | G14: 3 | L14: 100 | M14: 10018889 | N14: MAKITA AC ROTARY HAMMER 18MM HR1840J | O14: 2 | P14: 12 | Q14: 6 | S14: 12 | T14: 10
C15: 10018519 | D15: MAKITA TCT SAW BLADE METAL E-12918 | E15: E-12918 | F15: SCM190101 | G15: 7 | L15: 40 | M15: 10013669 | N15: MAKITA HAMMER-DRILL HP1630(16MM) 5/8" | O15: 3 | P15: 26 | Q15: 18 | S15: 13 | T15: 20
C16: 10019114 | D16: MAKITA STRING TRIMMER HEADB-05131 | E16: B-05131 | F16: SCM190202 | G16: 1 | L16: 130 | M16: 10048673 | N16: MAKITA AC HAMMER DRILL 13MM M8103KX2BX | O16: 3 | P16: 17 | Q16: 63 | S16: 14 | T16: 2
C17: 10048008 | D17: MAKITA STAPLE 4X19-419J B-04438 | E17: B-04438 | F17: SCM190109 | G17: 2 | L17: 50 | M17: 10019666 | N17: MAKITA ANGLE GRINDER (TOGGLE) GA4031 4" | O17: 3 | P17: 64 | Q17: 77 | S17: 15 | T17: 2
C18: 10048007 | D18: MAKITA STAPLE 4X13-413J B-04416 | E18: B-04416 | F18: SCM190109 | G18: 4 | L18: 30 | M18: 10018873 | N18: MAKITA ANGLE GRINDER 100MM T 850W M9513B | O18: 5 | P18: 37 | Q18: 126 | S18: 16 | T18: 2
C19: 10048006 | D19: MAKITA STAPLE 4X10-410J B-04400 | E19: B-04400 | F19: SCM190109 | G19: 2 | L19: 120 | M19: 10041607 | N19: MAKITA AC COMBINATION HAMMER HR2670X5 | O19: 2 | P19: 26 | Q19: 169 | S19: 17 | T19: 1
C20: 10018735 | D20: MAKITA SEGMENTSAW 100 TMA046 B-64808 | E20: B-64808 | F20: SCM190101 | G20: 5 | L20: 10 | M20: 10018890 | N20: MAKITA AC POWER PLANER 82MMM 1902B | P20: 21 | S20: 18 | T20: 1
C21: 10019622 | D21: MAKITA SDS-PLUS BIT5X160 HR2450 D-00038 | E21: D-00038 | F21: SCM190102 | G21: 175 | L21: 20 | M21: 10018157 | N21: MAKITA BATTERY BL1850B 18V 197280-8 | P21: 76 | S21: 19 | T21: 2
C22: 10050718 | D22: MAKITA SDS-PLUS BIT 12X210 D-00234 | E22: D-00234 | F22: SCM190102 | G22: 2 | L22: 60 | M22: 10019966 | N22: MAKITA TCT SAWBLADE 8" A-81767 18T | P22: 26 | S22: 20 | T22: 2
C23: 10019017 | D23: MAKITA SDS-MAX NEMESIS B-19978(16X540mm) | E23: B-19978 | F23: SCM190102 | G23: 4 | L23: 70 | M23: 10020128 | N23: MAKITA ANGLE GRINDER 9500NB (100MM) 4" | P23: 56 | S23: 21 | T23: 1
C24: 10018011 | D24: MAKITA SDS-MAX DRILL BIT 40X570 D-34160 | E24: D-34160 | F24: SCM190102 | G24: 9 | L24: 80 | M24: 10019960 | N24: MAKITA CUT-OFF WHEEL 14" A-89545 (355MM) | P24: 950 | S24: 22 | T24: 1
C25: 10018009 | D25: MAKITA SDS-MAX DRILL BIT 40X370 D-34154 | E25: D-34154 | F25: SCM190102 | G25: 6 | L25: 90 | M25: 10013672 | N25: MAKITA HAMMER-DRILL HP2050 (20MM) 3/4" | P25: 20 | S25: 23 | T25: 5
C26: 10018007 | D26: MAKITA SDS-MAX DRILL BIT 38X570 D-34148 | E26: D-34148 | F26: SCM190102 | G26: 10 | L26: 110 | M26: 10018991 | N26: MAKITA AC HAMMER DRILL 16MM M8100B | P26: 13 | S26: 24 | T26: 5
C27: 10018005 | D27: MAKITA SDS-MAX DRILL BIT 38X370 D-34132 | E27: D-34132 | F27: SCM190102 | G27: 7 | L27: 140 | M27: 10018157 | N27: MAKITA BATTERY BL1850B 18V 197280-8 | P27: 76 | S27: 25 | T27: 2
C28: 10018003 | D28: MAKITA SDS-MAX DRILL BIT 35X570 D-34126 | E28: D-34126 | F28: SCM190102 | G28: 7 | L28: 150 | M28: 10049780 | N28: MAKITA TCT SAWBLADE 185X25.4X24T D-81262 | P28: 24 | S28: 26 | T28: 1
C29: 10018001 | D29: MAKITA SDS-MAX DRILL BIT 35X370 D-34110 | E29: D-34110 | F29: SCM190102 | G29: 9 | S29: 27 | T29: 1
C30: 10017999 | D30: MAKITA SDS-MAX DRILL BIT 32X570 D-34104 | E30: D-34104 | F30: SCM190102 | G30: 9 | N30: Shop No. 164 S. HULHUMEEDHOO | S30: 28 | T30: 4
C31: 10017997 | D31: MAKITA SDS-MAX DRILL BIT 32X370 D-34095 | E31: D-34095 | F31: SCM190102 | G31: 6 | L31: 60 | M31: 10018723 | N31: MAKITA AC HAMMER DRILL 10MM HP0300 | O31: 2 | P31: 14 | Q31: 12 | S31: 29 | T31: 2
C32: 10017995 | D32: MAKITA SDS-MAX DRILL BIT 30X570 D-34089 | E32: D-34089 | F32: SCM190102 | G32: 4 | L32: 280 | M32: 10018872 | N32: MAKITA FINISHING SANDER M9203B | O32: 2 | P32: 17 | Q32: 13 | S32: 30 | T32: 2
C33: 10017993 | D33: MAKITA SDS-MAX DRILL BIT 30X370 D-34073 | E33: D-34073 | F33: SCM190102 | G33: 6 | L33: 30 | M33: 10018742 | N33: MAKITA AC BLOWER M4001B | O33: 2 | P33: 18 | Q33: 14 | S33: 31 | T33: 5
C34: 10017991 | D34: MAKITA SDS-MAX DRILL BIT 28X370 D-34051 | E34: D-34051 | F34: SCM190102 | G34: 8 | L34: 80 | M34: 10018725 | N34: MAKITA AC HAMMER DRILL 16MM M0801B | O34: 2 | P34: 17 | Q34: 18 | S34: 32 | T34: 2
C35: 10017989 | D35: MAKITA SDS-MAX DRILL BIT 25X540 D-34045 | E35: D-34045 | F35: SCM190102 | G35: 6 | L35: 330 | M35: 10019084 | N35: MAKITA ROTARY HAMMER HR2470X5 24MM | O35: 2 | P35: 21 | Q35: 36 | S35: 33 | T35: 1
C36: 10017987 | D36: MAKITA SDS-MAX DRILL BIT 25X340 D-34665 | E36: D-34665 | F36: SCM190102 | G36: 2 | L36: 190 | M36: 10013719 | N36: MAKITA CIRCULAR SAW 5008MG (210MM)8-1/4" | O36: 3 | P36: 10 | Q36: 37 | S36: 34 | T36: 3
C37: 10017985 | D37: MAKITA SDS-MAX DRILL BIT 24X540 D-34659 | E37: D-34659 | F37: SCM190102 | G37: 6 | L37: 20 | M37: 10018878 | N37: MAKITA AC ANGLE GRINDER 9556HPG | O37: 2 | P37: 28 | Q37: 40 | S37: 35 | T37: 1
C38: 10017983 | D38: MAKITA SDS-MAX DRILL BIT 22X540 D-34637 | E38: D-34637 | F38: SCM190102 | G38: 9 | L38: 300 | M38: 10013692 | N38: MAKITA IMPACT DRIVER TD0101F | O38: 3 | P38: 41 | Q38: 40 | S38: 36 | T38: 2
C39: 10018579 | D39: MAKITA SDS-MAX DRILL BIT 16-340 D-33934 | E39: D-33934 | F39: SCM190102 | G39: 1 | L39: 10 | M39: 10018921 | N39: MAKITA AC ANGLE GRINDER 4" 720W M9506B | O39: 3 | P39: 6 | Q39: 48 | S39: 37 | T39: 3
C40: 10019435 | D40: MAKITA SDS MAX DRILL BIT A-19495 HR4000C | E40: A-19495 | F40: SCM190102 | G40: 1 | L40: 140 | M40: 10018652 | N40: MAKITA ANGLE GRINDER 9556HNG | O40: 2 | P40: 39 | Q40: 68 | S40: 38 | T40: 2
C41: 10048026 | D41: MAKITA SAWBLADE 136X20X48T METAL E-23391 | E41: E-23391 | F41: SCM190201 | G41: 2 | L41: 110 | M41: 10019666 | N41: MAKITA ANGLE GRINDER (TOGGLE) GA4031 4" | O41: 3 | P41: 64 | Q41: 77 | S41: 39 | T41: 2
C42: 10018603 | D42: MAKITA RECIPRO SAW BLADE METAL B-55837 | E42: B-55837 | F42: SCM190101 | G42: 2 | L42: 260 | M42: 10019678 | N42: MAKITA FINISHING SANDER BO3710 | O42: 3 | P42: 30 | Q42: 84 | S42: 40 | T42: 3
...

Sheet Sheet2
C1: 10018874 | D1: MAKITA TRIMMER 6MM M3700B | E1: M3700B | F1: 47 | G1: 207 | H1: 1342.59 | I1: =H1*1.08 -> 1449.9972 | J1: 0.08 | K1: 1235.1852 | L1: 1334 | N1: Material | O1: Material Description | P1: Plnt | Q1: Unrestr. | S1: Material | T1: Material Description | U1: Unrestr.
C2: 10020105 | D2: MAKITA TABLE SAW 255MM MLT100 (10") | E2: MLT100 | F2: 26 | G2: 65 | H2: 11819.44 | I2: =H2*1.08 -> 12764.995 | J2: 0.1 | K2: 10637.037 | L2: 11488 | N2: 10013659 | O2: MAKITA DRILL DP4700 (13MM) 1/2" | P2: D004 | Q2: 115 | S2: 10013659 | T2: MAKITA DRILL DP4700 (13MM) 1/2" | U2: S002 | V2: 45 | W2: =VLOOKUP(S2,STOCK!A:C,3,0) -> DP4700 | Z2: Material | AB2: Material Description | AC2: PRICE
C3: 10018188 | D3: MAKITA SLOT CUT SAW 118MM CA5000X | E3: CA5000X | F3: 4 | G3: 8 | H3: 10662.04 | I3: =H3*1.08 -> 11515.003 | J3: 0.15 | K3: 9062.963 | L3: 9788 | N3: 10013669 | O3: MAKITA HAMMER-DRILL HP1630(16MM) 5/8" | P3: D004 | Q3: 24 | S3: 10013665 | T3: MAKITA C-LESS IMPACTDRVR TD090DWE 10.8V | U3: S002 | V3: 3 | W3: =VLOOKUP(S3,STOCK!A:C,3,0) -> TD090DWE | Z3: 10018727 | AA3: =VLOOKUP(Z3,STOCK!A:C,3,0) -> 3711 | AB3: MAKITA AC TRIMMER 6MM 3711 | AC3: =VLOOKUP(Z3,STOCK!A:G,7,0) -> 2150
C4: 10018593 | D4: MAKITA SLIDE COMPOUND SAW LS1019L | E4: LS1019L | F4: 15 | G4: 65 | H4: 14814.81 | I4: =H4*1.08 -> 15999.995 | J4: 0.1 | K4: 13333.333 | L4: 14400 | N4: 10013671 | O4: MAKITA DRILL 6412 (10MM) 3/8" | P4: D004 | Q4: 16 | S4: 10013669 | T4: MAKITA HAMMER-DRILL HP1630(16MM) 5/8" | U4: S002 | V4: 29 | W4: =VLOOKUP(S4,STOCK!A:C,3,0) -> HP1630 | Z4: 10013671 | AA4: =VLOOKUP(Z4,STOCK!A:C,3,0) -> 6412 | AB4: MAKITA DRILL 6412 (10MM) 3/8" | AC4: =VLOOKUP(Z4,STOCK!A:G,7,0) -> 1244
C5: 10020106 | D5: MAKITA SLIDE COMPOUND SAW LS0714 (7-1/2" | E5: LS0714 | F5: 5 | G5: 55 | H5: 10648.15 | I5: =H5*1.08 -> 11500.002 | J5: 0.1 | K5: 9583.3333 | L5: 10350 | N5: 10013672 | O5: MAKITA HAMMER-DRILL HP2050 (20MM) 3/4" | P5: D004 | Q5: 4 | S5: 10013671 | T5: MAKITA DRILL 6412 (10MM) 3/8" | U5: S002 | V5: 31 | W5: =VLOOKUP(S5,STOCK!A:C,3,0) -> 6412 | Z5: 10019931 | AA5: =VLOOKUP(Z5,STOCK!A:C,3,0) -> 6413 | AB5: MAKITA KEYLESS DRILL 6413 10MM | AC5: =VLOOKUP(Z5,STOCK!A:G,7,0) -> 1345
C6: 10018630 | D6: MAKITA SLIDE COMPOUND SAW 305MM LS1219L | E6: LS1219L | F6: 5 | G6: 39 | H6: 17013.89 | I6: =H6*1.08 -> 18375.001 | J6: 0.1 | K6: 15312.963 | L6: 16538 | N6: 10013684 | O6: MAKITA ROTARY HAMMER HR2810(3MODE) 28MM | P6: D004 | Q6: 25 | S6: 10013672 | T6: MAKITA HAMMER-DRILL HP2050 (20MM) 3/4" | U6: S002 | V6: 16 | W6: =VLOOKUP(S6,STOCK!A:C,3,0) -> HP2050 | Z6: 10013727 | AA6: =VLOOKUP(Z6,STOCK!A:C,3,0) -> 4327M | AB6: MAKITA JIGSAW 4327M (HOLE TYPE) | AC6: =VLOOKUP(Z6,STOCK!A:G,7,0) -> 1698
C7: 10019684 | D7: MAKITA SLIDE COMPOUND SAW 260MM LS1018L | E7: LS1018L | F7: 45 | G7: 128 | H7: 12101.85 | I7: =H7*1.08 -> 13069.998 | J7: 0.08 | K7: 11133.333 | L7: 12024 | N7: 10013692 | O7: MAKITA IMPACT DRIVER TD0101F | P7: D004 | Q7: 75 | S7: 10013673 | T7: MAKITA HAMMER-DRILL HP2070 (20MM) 3/4" | U7: S002 | V7: 10 | W7: =VLOOKUP(S7,STOCK!A:C,3,0) -> HP2070 | Z7: 10013716 | AA7: =VLOOKUP(Z7,STOCK!A:C,3,0) -> 5806B | AB7: MAKITA CIRCULAR SAW 5806B (185MM) 7-1/4" | AC7: =VLOOKUP(Z7,STOCK!A:G,7,0) -> 3230
C8: 10018159 | D8: MAKITA SHEAR WRENCH 6924N | E8: 6924N | F8: 1 | G8: 0 | H8: 5569.44 | I8: =H8*1.08 -> 6014.9952 | J8: 0.2 | K8: 4455.5556 | L8: 4812 | N8: 10013716 | O8: MAKITA CIRCULAR SAW 5806B (185MM) 7-1/4" | P8: D004 | Q8: 205 | S8: 10013683 | T8: MAKITA DEMOLITION HAMMER HM1306 (30MM) | U8: S002 | V8: 4 | W8: =VLOOKUP(S8,STOCK!A:C,3,0) -> HM1306 | Z8: 10020128 | AA8: =VLOOKUP(Z8,STOCK!A:C,3,0) -> 9500NB | AB8: MAKITA ANGLE GRINDER 9500NB (100MM) 4" | AC8: =VLOOKUP(Z8,STOCK!A:G,7,0) -> 2645
C9: 10019219 | D9: MAKITA SCROLL SAW SJ401 | E9: SJ401 | F9: 3 | G9: 3 | H9: 5407.41 | I9: =H9*1.08 -> 5840.0028 | J9: 0.15 | K9: 4596.2963 | L9: 4964 | N9: 10013719 | O9: MAKITA CIRCULAR SAW 5008MG (210MM)8-1/4" | P9: D004 | Q9: 39 | S9: 10013684 | T9: MAKITA ROTARY HAMMER HR2810(3MODE) 28MM | U9: S002 | V9: 9 | W9: =VLOOKUP(S9,STOCK!A:C,3,0) -> HR2810 | Z9: 10018652 | AA9: =VLOOKUP(Z9,STOCK!A:C,3,0) -> 9556HNG | AB9: MAKITA ANGLE GRINDER 9556HNG | AC9: =VLOOKUP(Z9,STOCK!A:G,7,0) -> 1659
C10: 10019813 | D10: MAKITA ROUTER 8MM RP0900 | E10: RP0900 | F10: 33 | G10: 71 | H10: 2342.59 | I10: =H10*1.08 -> 2529.9972 | J10: 0.1 | K10: 2108.3333 | L10: 2277 | N10: 10013721 | O10: MAKITA COMPOUND MITER SAW LS1040 10-1/4" | P10: D004 | Q10: 12 | S10: 10013692 | T10: MAKITA IMPACT DRIVER TD0101F | U10: S002 | V10: 37 | W10: =VLOOKUP(S10,STOCK!A:C,3,0) -> TD0101F | Z10: 10018878 | AA10: =VLOOKUP(Z10,STOCK!A:C,3,0) -> 9556HPG | AB10: MAKITA AC ANGLE GRINDER 9556HPG | AC10: =VLOOKUP(Z10,STOCK!A:G,7,0) -> 1415
C11: 10013684 | D11: MAKITA ROTARY HAMMER HR2810(3MODE) 28MM | E11: HR2810 | F11: 25 | G11: 140 | H11: 6166.67 | I11: =H11*1.08 -> 6660.0036 | J11: 0.08 | K11: 5673.1481 | L11: 6127 | N11: 10013727 | O11: MAKITA JIGSAW 4327M (HOLE TYPE) | P11: D004 | Q11: 20 | S11: 10013698 | T11: MAKITA POWER PLANER 1911B (4-3/8") 110MM | U11: S002 | V11: 8 | W11: =VLOOKUP(S11,STOCK!A:C,3,0) -> 1911B | Z11: 10019678 | AA11: =VLOOKUP(Z11,STOCK!A:C,3,0) -> BO3710 | AB11: MAKITA FINISHING SANDER BO3710 | AC11: =VLOOKUP(Z11,STOCK!A:G,7,0) -> 1593
C12: 10019084 | D12: MAKITA ROTARY HAMMER HR2470X5 24MM | E12: HR2470X5 | F12: 131 | G12: 515 | H12: 4259.26 | I12: =H12*1.08 -> 4600.0008 | J12: 0.08 | K12: 3918.5185 | L12: 4232 | N12: 10017895 | O12: MAKITA AC VACUUM CLEANER 20L VC2000L | P12: D004 | Q12: 3 | S12: 10013704 | T12: MAKITA PLANER 2012NB (304MM) 12" | U12: S002 | V12: 3 | W12: =VLOOKUP(S12,STOCK!A:C,3,0) -> 2012NB | Z12: 10019588 | AA12: =VLOOKUP(Z12,STOCK!A:C,3,0) -> BO5031 | AB12: MAKITA ORBITAL SANDER BO5031 ( 123MM) | AC12: =VLOOKUP(Z12,STOCK!A:G,7,0) -> 2870
C13: 10019841 | D13: MAKITA POWER PLANER KP0800X 3-1/4" | E13: KP0800X | F13: 71 | G13: 320 | H13: 3685.19 | I13: =H13*1.08 -> 3980.0052 | J13: 0.08 | K13: 3390.7407 | L13: 3662 | N13: 10017898 | O13: MAKITA DC HAMMER DRIVER DRILL DHP487RFJ | P13: D004 | Q13: 24 | S13: 10013710 | T13: MAKITA CIRCULAR SAW 5103N(335MM) 13-1/8" | U13: S002 | V13: 4 | W13: =VLOOKUP(S13,STOCK!A:C,3,0) -> 5103N | Z13: 10018660 | AA13: =VLOOKUP(Z13,STOCK!A:C,3,0) -> CLX224SAX1 | AB13: MAKITA COMBO KIT CLX224SAX1 | AC13: =VLOOKUP(Z13,STOCK!A:G,7,0) -> 5493
C14: 10013698 | D14: MAKITA POWER PLANER 1911B (4-3/8") 110MM | E14: 1911B | F14: 23 | G14: 64 | H14: 4966.67 | I14: =H14*1.08 -> 5364.0036 | J14: 0.1 | K14: 4470.3704 | L14: 4828 | N14: 10017904 | O14: MAKITA DC CLEANER 40V CL003GZ14 | P14: D004 | Q14: 9 | S14: 10013713 | T14: MAKITA CIRCULAR SAW N5900B (235MM)9-1/4" | U14: S002 | V14: 9 | W14: =VLOOKUP(S14,STOCK!A:C,3,0) -> N5900B | Z14: 10018170 | AA14: =VLOOKUP(Z14,STOCK!A:C,3,0) -> DHP482RFX1 | AB14: MAKITA C-LESS HAMMER DRILL DHP482RFX1 | AC14: =VLOOKUP(Z14,STOCK!A:G,7,0) -> 7350
... C32: 10018142 | D32: MAKITA LASER DISTANCE MEASURE LD030P 30M | E32: LD030P | F32: 5 | G32: 5 | H32: 1731.48 | I32: =H32*1.08 -> 1869.9984 | J32: 0.08 | K32: 1592.5926 | L32: 1720 | N32: 10018590 | O32: MAKITA C-LESS CIRCULAR SAW DSS610RTE | P32: D004 | Q32: 6 | S32: 10017908 | T32: MAKITA DC DRIVER DRILL BL 40V DF002GZ | U32: S002 | V32: 5 | W32: =VLOOKUP(S32,STOCK!A:C,3,0) -> DF002GZ | Z32: 10019051 | AA32: =VLOOKUP(Z32,STOCK!A:C,3,0) -> LW1401 | AB32: MAKITA CUTOFF MACHINE 14"(355MM) LW1401 | AC32: =VLOOKUP(Z32,STOCK!A:G,7,0) -> 5315
C33: 10019931 | D33: MAKITA KEYLESS DRILL 6413 10MM | E33: 6413 | F33: 86 | G33: 258 | H33: 1245.37 | I33: =H33*1.08 -> 1344.9996 | J33: 0.08 | K33: 1145.3704 | L33: 1237 | N33: 10018593 | O33: MAKITA SLIDE COMPOUND SAW LS1019L | P33: D004 | Q33: 16 | S33: 10017909 | T33: MAKITA DC HAMMER DRIVER 18V BL DHP489Z | U33: S002 | V33: 7 | W33: =VLOOKUP(S33,STOCK!A:C,3,0) -> DHP489Z | Z33: 10018890 | AA33: =VLOOKUP(Z33,STOCK!A:C,3,0) -> M1902B | AB33: MAKITA AC POWER PLANER 82MMM 1902B | AC33: =VLOOKUP(Z33,STOCK!A:G,7,0) -> 1900
C34: 10013727 | D34: MAKITA JIGSAW 4327M (HOLE TYPE) | E34: 4327M | F34: 66 | G34: 209 | H34: 1572.22 | I34: =H34*1.08 -> 1697.9976 | J34: 0.08 | K34: 1446.2963 | L34: 1562 | N34: 10018647 | O34: MAKITA C-LESS METAL SAW DCS552Z (5") | P34: D004 | Q34: 1 | S34: 10017910 | T34: MAKITA DC COMBI HAMMER DHR183Z | U34: S002 | V34: 3 | W34: =VLOOKUP(S34,STOCK!A:C,3,0) -> DHR183Z | Z34: 10018875 | AA34: =VLOOKUP(Z34,STOCK!A:C,3,0) -> M2401B | AB34: MAKITA PORTABLE CUT-OFF 355MM M2401B | AC34: =VLOOKUP(Z34,STOCK!A:G,7,0) -> 3695
C35: 10019356 | D35: MAKITA JIG SAW JV0600K (PIN) | E35: JV0600K | F35: 60 | G35: 254 | H35: 2760.19 | I35: =H35*1.08 -> 2981.0052 | J35: 0.08 | K35: 2539.8148 | L35: 2743 | N35: 10018652 | O35: MAKITA ANGLE GRINDER 9556HNG | P35: D004 | Q35: 92 | S35: 10017911 | T35: MAKITA DC CUTTER 18V BL 76MM DMC300Z | U35: S002 | V35: 5 | W35: =VLOOKUP(S35,STOCK!A:C,3,0) -> DMC300Z | Z35: 10018874 | AA35: =VLOOKUP(Z35,STOCK!A:C,3,0) -> M3700B | AB35: MAKITA TRIMMER 6MM M3700B | AC35: =VLOOKUP(Z35,STOCK!A:G,7,0) -> 1450
C36: 10018560 | D36: MAKITA JIG SAW 12V JV101DSAE | E36: JV101DSAE | F36: 11 | G36: 18 | H36: 4120.37 | I36: =H36*1.08 -> 4449.9996 | J36: 0.1 | K36: 3708.3333 | L36: 4005 | N36: 10018659 | O36: MAKITA DRILL 6305 (13MM) 1/2" | P36: D004 | Q36: 9 | S36: 10017912 | T36: MAKITA DC BAND SAW 18V 64MM DPB182Z | U36: S002 | V36: 1 | W36: =VLOOKUP(S36,STOCK!A:C,3,0) -> DPB182Z | Z36: 10018892 | AA36: =VLOOKUP(Z36,STOCK!A:C,3,0) -> M4000B | AB36: MAKITA AC BLOWER M4000B | AC36: =VLOOKUP(Z36,STOCK!A:G,7,0) -> 1225
C37: 10019233 | D37: MAKITA IMPACT WRENCH TW0350 12.7MM | E37: TW0350 | F37: 5 | G37: 9 | H37: 5300 | I37: =H37*1.08 -> 5724 | J37: 0.1 | K37: 4770.3704 | L37: 5152 | N37: 10018660 | O37: MAKITA COMBO KIT CLX224SAX1 | P37: D004 | Q37: 102 | S37: 10017915 | T37: MAKITA DC HEDGE TRIMMER 18V DUH751Z | U37: S002 | V37: 1 | W37: =VLOOKUP(S37,STOCK!A:C,3,0) -> DUH751Z | Z37: 10018896 | AA37: =VLOOKUP(Z37,STOCK!A:C,3,0) -> M5801B | AB37: MAKITA AC CIRCULAR SAW 185MM M5801B | AC37: =VLOOKUP(Z37,STOCK!A:G,7,0) -> 2025
C38: 10018432 | D38: MAKITA IMPACT WRENCH 18V BL DTW300RTJ | E38: DTW300RTJ | F38: 16 | G38: 33 | H38: 9393.52 | I38: =H38*1.08 -> 10145.002 | J38: 0.1 | K38: 8454.6296 | L38: 9131 | N38: 10018661 | O38: MAKITA HEAT GUN HG5030 | P38: D004 | Q38: 23 | S38: 10017924 | T38: MAKITA DC CIRCULAR SAW 40V 9" HS010GZ | U38: S002 | V38: 2 | W38: =VLOOKUP(S38,STOCK!A:C,3,0) -> HS010GZ | Z38: 10018491 | AA38: =VLOOKUP(Z38,STOCK!A:C,3,0) -> M6001B | AB38: MAKITA AC DRILL 10MM M6001B | AC38: =VLOOKUP(Z38,STOCK!A:G,7,0) -> 1110
C39: 10013692 | D39: MAKITA IMPACT DRIVER TD0101F | E39: TD0101F | F39: 249 | G39: 844 | H39: 1829.63 | I39: =H39*1.08 -> 1976.0004 | J39: 0.08 | K39: 1683.3333 | L39: 1818 | N39: 10018703 | O39: MAKITA DC CIRCULAR SAW 18V 165MM DSS610Z | P39: D004 | Q39: 6 | S39: 10017926 | T39: MAKITA DC CIRCULAR SAW 40V 6" HS012GZ | U39: S002 | V39: 2 | W39: =VLOOKUP(S39,STOCK!A:C,3,0) -> HS012GZ | Z39: 10018898 | AA39: =VLOOKUP(Z39,STOCK!A:C,3,0) -> M9200B | AB39: MAKITA AC FINISHING SANDER M9200B | AC39: =VLOOKUP(Z39,STOCK!A:G,7,0) -> 1032
C40: 10018428 | D40: MAKITA IMPACT DRIVER 18V BL DTD153RTE | E40: DTD153RTE | F40: 15 | G40: 14 | H40: 7990.74 | I40: =H40*1.08 -> 8629.9992 | J40: 0.1 | K40: 7191.6667 | L40: 7767 | N40: 10018708 | O40: MAKITA DC HAMMER DRILL 40V BL HP002GA201 | P40: D004 | Q40: 2 | S40: 10017927 | T40: MAKITA DC REBAR TYING TOOL 18V DTR181Z | U40: S002 | V40: 3 | W40: =VLOOKUP(S40,STOCK!A:C,3,0) -> DTR181Z | Z40: 10018872 | AA40: =VLOOKUP(Z40,STOCK!A:C,3,0) -> M9203B | AB40: MAKITA FINISHING SANDER M9203B | AC40: =VLOOKUP(Z40,STOCK!A:G,7,0) -> 1425
C41: 10019342 | D41: MAKITA HIGH PRESSURE WASHER HW151 | E41: HW151 | F41: 5 | G41: 7 | H41: 15942.59 | I41: =H41*1.08 -> 17217.997 | J41: 0.1 | K41: 14348.148 | L41: 15496 | N41: 10018720 | O41: MAKITA HAMMER DRILL 18V BL13MM DHP486RTE | P41: D004 | Q41: 42 | S41: 10017929 | T41: MAKITA DC IMPACT WRENCH 18V DTW700Z | U41: S002 | V41: 1 | W41: =VLOOKUP(S41,STOCK!A:C,3,0) -> DTW700Z | Z41: 10018900 | AA41: =VLOOKUP(Z41,STOCK!A:C,3,0) -> M9204B | AB41: MAKITA AC ORBIT SANDER 125MM M9204B | AC41: =VLOOKUP(Z41,STOCK!A:G,7,0) -> 1440
C42: 10019535 | D42: MAKITA HIGH PRESSURE WASHER HW102 | E42: HW102 | F42: 32 | G42: 59 | H42: 2652.78 | I42: =H42*1.08 -> 2865.0024 | J42: 0.1 | K42: 2387.963 | L42: 2579 | N42: 10018723 | O42: MAKITA AC HAMMER DRILL 10MM HP0300 | P42: D004 | Q42: 15 | S42: 10017932 | T42: MAKITA DC PLANER 40V BL AWS 82MM KP001GZ | U42: S002 | V42: 2 | W42: =VLOOKUP(S42,STOCK!A:C,3,0) -> KP001GZ | Z42: 10018921 | AA42: =VLOOKUP(Z42,STOCK!A:C,3,0) -> M9506B | AB42: MAKITA AC ANGLE GRINDER 4" 720W M9506B | AC42: =VLOOKUP(Z42,STOCK!A:G,7,0) -> 1235
C43: 10018586 | D43: MAKITA HEAT GUN HG6031VK | E43: HG6031VK | F43: 10 | G43: 80 | H43: 1939.81 | I43: =H43*1.08 -> 2094.9948 | J43: 0.1 | K43: 1745.3704 | L43: 1885 | N43: 10018725 | O43: MAKITA AC HAMMER DRILL 16MM M0801B | P43: D004 | Q43: 21 | S43: 10017935 | T43: MAKITA MULTIFUNCTION POW.HEAD 18V DUX18Z | U43: S002 | V43: 2 | W43: =VLOOKUP(S43,STOCK!A:C,3,0) -> DUX18Z | Z43: 10018873 | AA43: =VLOOKUP(Z43,STOCK!A:C,3,0) -> M9513B | AB43: MAKITA ANGLE GRINDER 100MM T 850W M9513B | AC43: =VLOOKUP(Z43,STOCK!A:G,7,0) -> 1260
C44: 10018661 | D44: MAKITA HEAT GUN HG5030 | E44: HG5030 | F44: 66 | G44: 198 | H44: 1009.26 | I44: =H44*1.08 -> 1090.0008 | J44: 0.08 | K44: 928.7037 | L44: 1003 | N44: 10018726 | O44: MAKITA AC CIRCULAR SAW 165MM HS6600 | P44: D004 | Q44: 38 | S44: 10017936 | T44: MAKITA DC MICROWAVE 40V 8L 500W MW001GZ | U44: S002 | V44: 1 | W44: =VLOOKUP(S44,STOCK!A:C,3,0) -> MW001GZ | Z44: 10013713 | AA44: =VLOOKUP(Z44,STOCK!A:C,3,0) -> N5900B | AB44: MAKITA CIRCULAR SAW N5900B (235MM)9-1/4" | AC44: =VLOOKUP(Z44,STOCK!A:G,7,0) -> 4210
C45: 10013673 | D45: MAKITA HAMMER-DRILL HP2070 (20MM) 3/4" | E45: HP2070 | F45: 22 | G45: 101 | H45: 3666.67 | I45: =H45*1.08 -> 3960.0036 | J45: 0.08 | K45: 3373.1481 | L45: 3643 | N45: 10018727 | O45: MAKITA AC TRIMMER 6MM 3711 | P45: D004 | Q45: 57 | S45: 10017938 | T45: MAKITA DC POLISHER 40V BL 180MM PV001GZ | U45: S002 | V45: 4 | W45: =VLOOKUP(S45,STOCK!A:C,3,0) -> PV001GZ | Z45: 10013692 | AA45: =VLOOKUP(Z45,STOCK!A:C,3,0) -> TD0101F | AB45: MAKITA IMPACT DRIVER TD0101F | AC45: =VLOOKUP(Z45,STOCK!A:G,7,0) -> 2085
... C47: 10013669 | D47: MAKITA HAMMER-DRILL HP1630(16MM) 5/8" | E47: HP1630 | F47: 108 | G47: 279 | H47: 1666.67 | I47: =H47*1.08 -> 1800.0036 | J47: 0.08 | K47: 1533.3333 | L47: 1656 | N47: 10018746 | O47: MAKITA AC DEMOLITION HAMMER 5KG HM0810TA | P47: D004 | Q47: 4 | S47: 10017943 | T47: MAKITA DC CHAIN SAW 40V 16" UC012GZ | U47: S002 | V47: 1 | W47: =VLOOKUP(S47,STOCK!A:C,3,0) -> UC012GZ | Z47: 10019144 | AA47: =VLOOKUP(Z47,STOCK!A:C,3,0) -> UB1103 | AB47: MAKITA BLOWER UB1103 | AC47: =VLOOKUP(Z47,STOCK!A:G,7,0) -> 1755
C48: 10018751 | D48: MAKITA HAMMER DRIVER DRILL18V BL DHP486Z | E48: DHP486Z | F48: 11 | G48: 31 | H48: 4787.04 | I48: =H48*1.08 -> 5170.0032 | J48: 0.1 | K48: 4308.3333 | L48: 4653 | N48: 10018765 | O48: MAKITA DC ROTARY HAMMER 40V 40MM HR005GZ | P48: D004 | Q48: 3 | S48: 10017945 | T48: MAKITA DC CHAIN SAW 40V 12" UC014GZ | U48: S002 | V48: 1 | W48: =VLOOKUP(S48,STOCK!A:C,3,0) -> UC014GZ
C49: 10031417 | D49: MAKITA HAMMER DRIVER DRILL BL DHP489RTJ | E49: DHP489RTJ | F49: 15 | G49: 32 | H49: 9333.33 | I49: =H49*1.08 -> 10079.996 | J49: 0.1 | K49: 8400 | L49: 9072 | N49: 10018872 | O49: MAKITA FINISHING SANDER M9203B | P49: D004 | Q49: 21 | S49: 10017947 | T49: MAKITA DC CHAIN SAW 12V BL 100MM UC100DZ | U49: S002 | V49: 2 | W49: =VLOOKUP(S49,STOCK!A:C,3,0) -> UC100DZ
C50: 10041606 | D50: MAKITA HAMMER DRIVER DRILL 40V HP002GZ | E50: HP002GZ | F50: 5 | G50: 12 | H50: 3106.48 | I50: =H50*1.08 -> 3354.9984 | J50: 0.08 | K50: 2858.3333 | L50: 3087 | N50: 10018873 | O50: MAKITA ANGLE GRINDER 100MM T 850W M9513B | P50: D004 | Q50: 144 | S50: 10017949 | T50: MAKITA DC HEDGE TRIMMER 40V UH014GZ | U50: S002 | V50: 2 | W50: =VLOOKUP(S50,STOCK!A:C,3,0) -> UH014GZ
C51: 10049777 | D51: MAKITA HAMMER DRIVER DRILL 18V DHP490WVX | E51: DHP490WVX | F51: 139 | G51: 0 | H51: 3046.3 | I51: =H51*1.08 -> 3290.004 | J51: 0.2 | K51: 2437.037 | L51: 2632 | N51: 10018874 | O51: MAKITA TRIMMER 6MM M3700B | P51: D004 | Q51: 33 | S51: 10017953 | T51: MAKITA DC GARDEN SPRAYER 12V 5L US053DZ | U51: S002 | V51: 1 | W51: =VLOOKUP(S51,STOCK!A:C,3,0) -> US053DZ
C52: 10018425 | D52: MAKITA HAMMER DRIVER DRILL 18V DHP453RYE | E52: DHP453RYE | F52: 24 | G52: 1 | H52: 5101.85 | I52: =H52*1.08 -> 5509.998 | J52: 0.1 | K52: 4591.6667 | L52: 4959 | N52: 10018875 | O52: MAKITA PORTABLE CUT-OFF 355MM M2401B | P52: D004 | Q52: 47 | S52: 10017957 | T52: MAKITA DC VACUUM CLEANER 40V VC008GZ04 | U52: S002 | V52: 2 | W52: =VLOOKUP(S52,STOCK!A:C,3,0) -> VC008GZ04
C53: 10018720 | D53: MAKITA HAMMER DRILL 18V BL13MM DHP486RTE | E53: DHP486RTE | F53: 94 | G53: 382 | H53: 9763.89 | I53: =H53*1.08 -> 10545.001 | J53: 0.08 | K53: 8982.4074 | L53: 9701 | N53: 10018878 | O53: MAKITA AC ANGLE GRINDER 9556HPG | P53: D004 | Q53: 52 | S53: 10017958 | T53: MAKITA DC COMBI HAMMER 40V HR007GZ | U53: S002 | V53: 2 | W53: =VLOOKUP(S53,STOCK!A:C,3,0) -> HR007GZ
C54: 10018721 | D54: MAKITA HAMMER DRILL 18V BL 13MM DHP487Z | E54: DHP487Z | F54: 15 | G54: 43 | H54: 2351.85 | I54: =H54*1.08 -> 2539.998 | J54: 0.1 | K54: 2116.6667 | L54: 2286 | N54: 10018879 | O54: MAKITA PN BRAD NAILER 50MM AF506 | P54: D004 | Q54: 28 | S54: 10017959 | T54: MAKITA DC VACUUM CLEANER 40V VC009GZ | U54: S002 | V54: 2 | W54: =VLOOKUP(S54,STOCK!A:C,3,0) -> VC009GZ
C55: 10018434 | D55: MAKITA FINISHING SANDER110X110MM BO4510H | E55: BO4510H | F55: 4 | G55: 1 | H55: 1194.44 | I55: =H55*1.08 -> 1289.9952 | J55: 0.1 | K55: 1075 | L55: 1161 | N55: 10018889 | O55: MAKITA AC ROTARY HAMMER 18MM HR1840J | P55: D004 | Q55: 8 | S55: 10017960 | T55: MAKITA DC CIRCULAR SAW 40V 235MM HS009GZ | U55: S002 | V55: 3 | W55: =VLOOKUP(S55,STOCK!A:C,3,0) -> HS009GZ
C56: 10018872 | D56: MAKITA FINISHING SANDER M9203B | E56: M9203B | F56: 56 | G56: 141 | H56: 1259.26 | I56: =H56*1.08 -> 1360.0008 | J56: 0.08 | K56: 1158.3333 | L56: 1251 | N56: 10018890 | O56: MAKITA AC POWER PLANER 82MMM 1902B | P56: D004 | Q56: 10 | S56: 10017965 | T56: MAKITA T.C.T SAW BLADE 7" 60T P-67963 | U56: S002 | V56: 50 | W56: =VLOOKUP(S56,STOCK!A:C,3,0) -> P-67963
C57: 10020113 | D57: MAKITA FINISHING SANDER BO4556 | E57: BO4556 | F57: 35 | G57: 99 | H57: 1490.74 | I57: =H57*1.08 -> 1609.9992 | J57: 0.1 | K57: 1341.6667 | L57: 1449 | N57: 10018891 | O57: MAKITA AC CONCRETE PLANER 125MM PC5010C | P57: D004 | Q57: 2 | S57: 10017967 | T57: MAKITA T.C.T SAW BLADE 7" S.S B-31697 | U57: S002 | V57: 8 | W57: =VLOOKUP(S57,STOCK!A:C,3,0) -> B-31697
C58: 10019678 | D58: MAKITA FINISHING SANDER BO3710 | E58: BO3710 | F58: 276 | G58: 698 | H58: 1475 | I58: =H58*1.08 -> 1593 | J58: 0.08 | K58: 1357.4074 | L58: 1466 | N58: 10018892 | O58: MAKITA AC BLOWER M4000B | P58: D004 | Q58: 5 | S58: 10017972 | T58: MAKITA DC IMPACT WRENCH 40V TW001GM204 | U58: S002 | V58: 2 | W58: =VLOOKUP(S58,STOCK!A:C,3,0) -> TW001GM204
...

Sheet Sheet3
A2: SPECIAL OFFER 20% | B2: SPECIAL OFFER 20% | C2: SPECIAL OFFER 20% | D2: SPECIAL OFFER 10% | E2: SPECIAL OFFER 10% | F2: SPECIAL OFFER 10% | K2: 12580 | L2: 1 | M2: 11806 | N2: 2 | O2: 11830 | P2: 3 | Q2: 13444 | R2: 4 | S2: 11930 | T2: 5 | U2: 13096 | V2: 6 | W2: 11830 | X2: 7 | Y2: 12770 | Z2: 8 | AA2: 11562 | AB2: 9 | AC2: 11565 | AD2: 10 | AE2: 12484 | AF2: 11 | AG2: 11830 | AH2: 12 | AI2: 12792 | AJ2: 13 | AL2: 14
A3: SPECIAL OFFER 30% | B3: SPECIAL OFFER 30% | C3: SPECIAL OFFER 30% | D3: SPECIAL OFFER 10% | E3: SPECIAL OFFER 10% | F3: SPECIAL OFFER 10% | K3: 13493 | L3: 1 | M3: 13576 | N3: 2 | O3: 12912 | P3: 3 | Q3: 13060 | R3: 4 | S3: 11996 | T3: 5 | U3: 11581 | V3: 6 | W3: 11881 | X3: 7 | Y3: 13500 | Z3: 8 | AA3: 13505 | AB3: 9 | AC3: HR2470 | AD3: 10 | AE3: 13505 | AF3: 11 | AH3: 12 | AI3: 13101 | AJ3: 13 | AL3: 14
A4: SPECIAL OFFER 40% | B4: SPECIAL OFFER 40% | C4: SPECIAL OFFER 40% | D4: SPECIAL OFFER 10% | E4: SPECIAL OFFER 10% | F4: SPECIAL OFFER 10% | K4: 13584 | L4: 1 | M4: 13127 | N4: 2 | O4: 11668 | P4: 3 | Q4: 11806 | R4: 4 | S4: 13364 | T4: 5 | U4: 11834 | V4: 6 | W4: 11404 | X4: 7 | Y4: 13454 | Z4: 8 | AA4: 13563 | AB4: 9 | AC4: 12970 | AD4: 10 | AE4: 13127 | AF4: 11 | AH4: 12 | AI4: 13127 | AJ4: 13 | AL4: 14
A5: SPECIAL OFFER 50% | B5: SPECIAL OFFER 50% | C5: SPECIAL OFFER 50% | D5: SPECIAL OFFER 20% | E5: SPECIAL OFFER 20% | F5: SPECIAL OFFER 20% | K5: 13570 | L5: 1 | M5: 13492 | N5: 2 | O5: 11806 | P5: 3 | Q5: 13454 | R5: 4 | S5: 13377 | T5: 5 | U5: 11981 | V5: 6 | W5: 12049 | X5: 7 | Y5: 11505 | Z5: 8 | AA5: 13508 | AB5: 9 | AC5: 12770 | AD5: 10 | AF5: 11 | AH5: 12 | AJ5: 13 | AL5: 14
A6: SPECIAL OFFER 50% | B6: SPECIAL OFFER 50% | C6: SPECIAL OFFER 50% | D6: SPECIAL OFFER 20% | E6: SPECIAL OFFER 20% | F6: SPECIAL OFFER 20% | K6: 13518 | L6: 1 | M6: 11386 | N6: 2 | O6: 11592 | P6: 3 | R6: 4 | S6: 13465 | T6: 5 | U6: 11458 | V6: 6 | W6: 11177 | X6: 7 | Z6: 8 | AA6: 11545 | AB6: 9 | AC6: 13218 | AD6: 10 | AF6: 11 | AH6: 12 | AJ6: 13 | AL6: 14
A7: SPECIAL OFFER 50% | B7: SPECIAL OFFER 50% | C7: SPECIAL OFFER 50% | D7: SPECIAL OFFER 20% | E7: SPECIAL OFFER 20% | F7: SPECIAL OFFER 20% | L7: 1 | M7: 10160 | N7: 2 | O7: 11734 | P7: 3 | R7: 4 | S7: 12422 | T7: 5 | U7: 12113 | V7: 6 | W7: 13428 | X7: 7 | Z7: 8 | AA7: 13447 | AB7: 9 | AD7: 10 | AF7: 11 | AH7: 12 | AJ7: 13 | AL7: 14
A8: SPECIAL OFFER 50% | B8: SPECIAL OFFER 50% | C8: SPECIAL OFFER 50% | D8: SPECIAL OFFER 20% | E8: SPECIAL OFFER 20% | F8: SPECIAL OFFER 20% | L8: 1 | N8: 2 | O8: 12413 | P8: 3 | R8: 4 | T8: 5 | U8: 12703 | V8: 6 | W8: 13204 | X8: 7 | Z8: 8 | AB8: 9 | AD8: 10 | AF8: 11 | AH8: 12 | AJ8: 13 | AL8: 14
A9: SPECIAL OFFER 50% | B9: SPECIAL OFFER 50% | C9: SPECIAL OFFER 50% | D9: SPECIAL OFFER 20% | E9: SPECIAL OFFER 20% | F9: SPECIAL OFFER 20% | L9: 1 | N9: 2 | O9: 11592 | P9: 3 | R9: 4 | T9: 5 | U9: 11386 | V9: 6 | X9: 7 | Z9: 8 | AB9: 9 | AD9: 10 | AF9: 11 | AH9: 12 | AL9: 14
A10: SPECIAL OFFER 50% | B10: SPECIAL OFFER 50% | C10: SPECIAL OFFER 50% | D10: SPECIAL OFFER 30% | E10: SPECIAL OFFER 30% | F10: SPECIAL OFFER 30% | L10: 1 | N10: 2 | O10: 12242 | P10: 3 | R10: 4 | T10: 5 | U10: 11816 | V10: 6 | X10: 7 | Z10: 8 | AB10: 9 | AD10: 10 | AF10: 11 | AH10: 12 | AL10: 14
A11: SPECIAL OFFER 50% | B11: SPECIAL OFFER 50% | C11: SPECIAL OFFER 50% | D11: SPECIAL OFFER 30% | E11: SPECIAL OFFER 30% | F11: SPECIAL OFFER 30% | L11: 1 | N11: 2 | O11: 13488 | P11: 3 | R11: 4 | T11: 5 | U11: 11669 | V11: 6 | X11: 7 | Z11: 8 | AB11: 9 | AD11: 10 | AF11: 11 | AH11: 12 | AL11: 14
A12: SPECIAL OFFER 50% | B12: SPECIAL OFFER 50% | C12: SPECIAL OFFER 50% | D12: SPECIAL OFFER 30% | E12: SPECIAL OFFER 30% | F12: SPECIAL OFFER 30% | L12: 1 | N12: 2 | O12: 13567 | P12: 3 | R12: 4 | T12: 5 | U12: 12700 | V12: 6 | X12: 7 | Z12: 8 | AB12: 9 | AD12: 10 | AF12: 11 | AH12: 12 | AL12: 14
A13: SPECIAL OFFER 50% | B13: SPECIAL OFFER 50% | C13: SPECIAL OFFER 50% | D13: SPECIAL OFFER 30% | E13: SPECIAL OFFER 30% | F13: SPECIAL OFFER 30% | L13: 1 | N13: 2 | O13: 11692 | P13: 3 | R13: 4 | T13: 5 | U13: 13550 | V13: 6 | X13: 7 | Z13: 8 | AB13: 9 | AD13: 10 | AF13: 11 | AH13: 12 | AL13: 14
A14: SPECIAL OFFER 50% | B14: SPECIAL OFFER 50% | C14: SPECIAL OFFER 50% | D14: SPECIAL OFFER 30% | E14: SPECIAL OFFER 30% | F14: SPECIAL OFFER 30% | L14: 1 | N14: 2 | P14: 3 | R14: 4 | T14: 5 | U14: 11990 | V14: 6 | X14: 7 | Z14: 8 | AB14: 9 | AD14: 10 | AF14: 11 | AH14: 12 | AL14: 14
A15: SPECIAL OFFER 50% | B15: SPECIAL OFFER 50% | C15: SPECIAL OFFER 50% | D15: SPECIAL OFFER 40% | E15: SPECIAL OFFER 40% | F15: SPECIAL OFFER 40% | L15: 1 | N15: 2 | P15: 3 | R15: 4 | T15: 5 | U15: 11883 | V15: 6 | X15: 7 | Z15: 8 | AB15: 9 | AD15: 10 | AF15: 11 | AH15: 12 | AL15: 14
A16: SPECIAL OFFER 50% | B16: SPECIAL OFFER 50% | C16: SPECIAL OFFER 50% | D16: SPECIAL OFFER 40% | E16: SPECIAL OFFER 40% | F16: SPECIAL OFFER 40% | L16: 1 | N16: 2 | P16: 3 | R16: 4 | T16: 5 | V16: 6 | X16: 7 | Z16: 8 | AB16: 9 | AD16: 10 | AF16: 11 | AH16: 12 | AL16: 14
A17: SPECIAL OFFER 50% | B17: SPECIAL OFFER 50% | C17: SPECIAL OFFER 50% | D17: SPECIAL OFFER 50% | E17: SPECIAL OFFER 50% | F17: SPECIAL OFFER 50%
A18: SPECIAL OFFER 50% | B18: SPECIAL OFFER 50% | C18: SPECIAL OFFER 50% | D18: SPECIAL OFFER 50% | E18: SPECIAL OFFER 50% | F18: SPECIAL OFFER 50%
A19: SPECIAL OFFER 50% | B19: SPECIAL OFFER 50% | C19: SPECIAL OFFER 50% | D19: SPECIAL OFFER 50% | E19: SPECIAL OFFER 50% | F19: SPECIAL OFFER 50%
A20: SPECIAL OFFER 50% | B20: SPECIAL OFFER 50% | C20: SPECIAL OFFER 50% | D20: SPECIAL OFFER 50% | E20: SPECIAL OFFER 50% | F20: SPECIAL OFFER 50%
A21: SPECIAL OFFER 70% | B21: SPECIAL OFFER 70% | C21: SPECIAL OFFER 70% | D21: SPECIAL OFFER 50% | E21: SPECIAL OFFER 50% | F21: SPECIAL OFFER 50%

Sheet Sheet1
K2: Material | L2: Material Description | M2: Unrestr.
B3: ARTICLE | C3: DESCRIPTION | D3: NEW ORDER | F3: Material | G3: Material Description | H3: Unrestr. | P3: =VLOOKUP(R3,'[1]MAKITA MASTERSHEET'!$E:$G,3,0) -> 10020027 | Q3: MAKITA TCT. SAW BLADE A-81898 6" | R3: =VLOOKUP(Q3,'[1]MAKITA MASTERSHEET'!$D:$E,2,0) -> A-81898 | S3: MAKITA | T3: =VLOOKUP(R3,'[1]J NEW PRICE'!$A:$B,2,0) -> T.C.T SAW BLADE 160X20X40T WOOD | U3: 10020027 | V3: MAKITA TCT SAWBLADE 160X20X40T A-81898 | W3: =LEN(V3) -> 38
D4: EA | K4: 10013659 | L4: MAKITA DRILL DP4700 (13MM) 1/2" | M4: 65 | P4: =VLOOKUP(R4,'[1]MAKITA MASTERSHEET'!$E:$G,3,0) -> 10019339 | Q4: MAKITA TCT SAW BLADE METAL B-23117 136MM | R4: =VLOOKUP(Q4,'[1]MAKITA MASTERSHEET'!$D:$E,2,0) -> B-23117 | S4: MAKITA | T4: =VLOOKUP(R4,'[1]J NEW PRICE'!$A:$B,2,0) -> T.C.T SAW BLADE 136X20X56T S.STEEL | U4: 10019339 | V4: MAKITA TCT SAWBLADE 136MM 56T SS B-23117 | W4: =LEN(V4) -> 40
B5: 10046422 | C5: MAKITA DC HAMMER DRV DRILL 12V HP332DSME | D5: 2 | F5: 10013659 | G5: MAKITA DRILL DP4700 (13MM) 1/2" | H5: 64 | K5: 10013669 | L5: MAKITA HAMMER-DRILL HP1630(16MM) 5/8" | M5: 82 | P5: =VLOOKUP(R5,'[1]MAKITA MASTERSHEET'!$E:$G,3,0) -> 10019210 | Q5: MAKITA TCT SAW BLADE METAL B-07319 136MM | R5: =VLOOKUP(Q5,'[1]MAKITA MASTERSHEET'!$D:$E,2,0) -> B-07319 | S5: MAKITA | T5: =VLOOKUP(R5,'[1]J NEW PRICE'!$A:$B,2,0) -> T.C.T SAW BLADE 136X20X30T METAL | U5: 10019210 | V5: MAKITA TCT SAWBLADE 136MM 30T M B-07319 | W5: =LEN(V5) -> 39
B6: 10018759 | C6: MAKITA DC COMBO KIT 18V DLX2131JX7 | D6: 2 | F6: 10013665 | G6: MAKITA C-LESS IMPACTDRVR TD090DWE 10.8V | H6: 3 | K6: 10013671 | L6: MAKITA DRILL 6412 (10MM) 3/8" | M6: 15 | P6: =VLOOKUP(R6,'[1]MAKITA MASTERSHEET'!$E:$G,3,0) -> 10041624 | Q6: MAKITA TCT SAW BLADE B-17158 | R6: =VLOOKUP(Q6,'[1]MAKITA MASTERSHEET'!$D:$E,2,0) -> B-17158 | S6: MAKITA | T6: =VLOOKUP(R6,'[1]J NEW PRICE'!$A:$B,2,0) -> T.C.T SAW BLADE 203X25.4X80T WOOD | U6: 10041624 | V6: MAKITA TCT SAWBLADE 203X25.4X80T B-17158 | W6: =LEN(V6) -> 40
B7: 10019051 | C7: MAKITA CUTOFF MACHINE 14"(355MM) LW1401 | D7: 2 | F7: 10013669 | G7: MAKITA HAMMER-DRILL HP1630(16MM) 5/8" | H7: 16 | K7: 10013672 | L7: MAKITA HAMMER-DRILL HP2050 (20MM) 3/4" | M7: 18 | P7: =VLOOKUP(R7,'[1]MAKITA MASTERSHEET'!$E:$G,3,0) -> 10018519 | Q7: MAKITA TCT SAW BLADE METAL E-12918 | R7: =VLOOKUP(Q7,'[1]MAKITA MASTERSHEET'!$D:$E,2,0) -> E-12918 | S7: MAKITA | T7: =VLOOKUP(R7,'[1]J NEW PRICE'!$A:$B,2,0) -> T.C.T SAW BLADE 185X20X45T METAL EFFICUT | U7: 10018519 | V7: MAKITA SAWBLADE 185MM 45T M EFF E-12918 | W7: =LEN(V7) -> 39
B8: 10018875 | C8: MAKITA PORTABLE CUT-OFF 355MM M2401B | D8: 2 | F8: 10013671 | G8: MAKITA DRILL 6412 (10MM) 3/8" | H8: 23 | K8: 10013673 | L8: MAKITA HAMMER-DRILL HP2070 (20MM) 3/4" | M8: 9 | P8: =VLOOKUP(R8,'[1]MAKITA MASTERSHEET'!$E:$G,3,0) -> 10018604 | Q8: MAKITA TC RECIPRO SAW BLADE B-55594 | R8: =VLOOKUP(Q8,'[1]MAKITA MASTERSHEET'!$D:$E,2,0) -> B-55594 | S8: MAKITA | T8: =VLOOKUP(R8,'[1]J NEW PRICE'!$A:$B,2,0) -> RECIPRO SAW BLADE 305MM TC/HM (1PCS) | U8: 10018604 | V8: MAKITA RECIPRO SAWBLADE 305MM B-55594 | W8: =LEN(V8) -> 37
B9: 10013721 | C9: MAKITA COMPOUND MITER SAW LS1040 10-1/4" | D9: 1 | F9: 10013672 | G9: MAKITA HAMMER-DRILL HP2050 (20MM) 3/4" | H9: 15 | K9: 10013684 | L9: MAKITA ROTARY HAMMER HR2810(3MODE) 28MM | M9: 21 | P9: =VLOOKUP(R9,'[1]MAKITA MASTERSHEET'!$E:$G,3,0) -> 10018531 | Q9: MAKITA T.C.T SAW BLADE WOOD P-67957 | R9: =VLOOKUP(Q9,'[1]MAKITA MASTERSHEET'!$D:$E,2,0) -> P-67957 | S9: MAKITA | T9: =VLOOKUP(R9,'[1]J NEW PRICE'!$A:$B,2,0) -> T.C.T SAW BLADE 185X20X40T WOOD | U9: 10018531 | V9: MAKITA TCT SAWBLADE 185X20X40T P-67957 | W9: =LEN(V9) -> 38
B10: 10049777 | C10: MAKITA HAMMER DRIVER DRILL 18V DHP490WVX | D10: 4 | F10: 10013673 | G10: MAKITA HAMMER-DRILL HP2070 (20MM) 3/4" | H10: 3 | K10: 10013692 | L10: MAKITA IMPACT DRIVER TD0101F | M10: 250 | P10: =VLOOKUP(R10,'[1]MAKITA MASTERSHEET'!$E:$G,3,0) -> 10018543 | Q10: MAKITA T.C.T SAW BLADE WOOD D-50538 | R10: =VLOOKUP(Q10,'[1]MAKITA MASTERSHEET'!$D:$E,2,0) -> D-50538 | S10: MAKITA | T10: =VLOOKUP(R10,'[1]J NEW PRICE'!$A:$B,2,0) -> T.C.T SAW BLADE 185X25.4X40T WOOD | U10: 10018543 | V10: MAKITA TCT SAWBLADE 185X25.4X40T D-50538 | W10: =LEN(V10) -> 40
B11: 10045280 | C11: MAKITA DC HAMMER DRILL 13MM DHP490RFX1 | D11: 4 | F11: 10013680 | G11: MAKITA ROTARY HAMMER HR3200C 3MODE(32MM) | H11: 1 | K11: 10013710 | L11: MAKITA CIRCULAR SAW 5103N(335MM) 13-1/8" | M11: 3 | P11: =VLOOKUP(R11,'[1]MAKITA MASTERSHEET'!$E:$G,3,0) -> 10018533 | Q11: MAKITA T.C.T SAW BLADE WOOD D-29066 | R11: =VLOOKUP(Q11,'[1]MAKITA MASTERSHEET'!$D:$E,2,0) -> D-29066 | S11: MAKITA | T11: =VLOOKUP(R11,'[1]J NEW PRICE'!$A:$B,2,0) -> T.C.T SAW BLADE 210X25X24T WOOD | U11: 10018533 | V11: MAKITA TCT SAWBLADE 210X25X24T D-29066 | W11: =LEN(V11) -> 38
B12: 10045279 | C12: MAKITA DC HAMMER DRILL 13MM DHP490RF | D12: 4 | F12: 10013683 | G12: MAKITA DEMOLITION HAMMER HM1306 (30MM) | H12: 7 | K12: 10013713 | L12: MAKITA CIRCULAR SAW N5900B (235MM)9-1/4" | M12: 18 | P12: =VLOOKUP(R12,'[1]MAKITA MASTERSHEET'!$E:$G,3,0) -> 10018545 | Q12: MAKITA T.C.T SAW BLADE WOOD D-03349 | R12: =VLOOKUP(Q12,'[1]MAKITA MASTERSHEET'!$D:$E,2,0) -> D-03349 | S12: MAKITA | T12: =VLOOKUP(R12,'[1]J NEW PRICE'!$A:$B,2,0) -> T.C.T SAW BLADE 165X20X40T WOOD | U12: 10018545 | V12: MAKITA TCT SAWBLADE 165X20X40T D-03349 | W12: =LEN(V12) -> 38
F13: 10013684 | G13: MAKITA ROTARY HAMMER HR2810(3MODE) 28MM | H13: 16 | K13: 10013716 | L13: MAKITA CIRCULAR SAW 5806B (185MM) 7-1/4" | M13: 290 | P13: =VLOOKUP(R13,'[1]MAKITA MASTERSHEET'!$E:$G,3,0) -> 10018417 | Q13: MAKITA T.C.T SAW BLADE WOOD B-17142 | R13: =VLOOKUP(Q13,'[1]MAKITA MASTERSHEET'!$D:$E,2,0) -> B-17142 | S13: MAKITA | T13: =VLOOKUP(R13,'[1]J NEW PRICE'!$A:$B,2,0) -> T.C.T SAW BLADE 203X25.4X60T WOOD | U13: 10018417 | V13: MAKITA TCT SAWBLADE 203X25.4X60T B-17142 | W13: =LEN(V13) -> 40
F14: 10013692 | G14: MAKITA IMPACT DRIVER TD0101F | H14: 32 | K14: 10013719 | L14: MAKITA CIRCULAR SAW 5008MG (210MM)8-1/4" | M14: 60 | P14: =VLOOKUP(R14,'[1]MAKITA MASTERSHEET'!$E:$G,3,0) -> 10018541 | Q14: MAKITA T.C.T SAW BLADE WOOD A-86038 | R14: =VLOOKUP(Q14,'[1]MAKITA MASTERSHEET'!$D:$E,2,0) -> A-86038 | S14: MAKITA | T14: =VLOOKUP(R14,'[1]J NEW PRICE'!$A:$B,2,0) -> T.C.T SAW BLADE 165X20X24T WOOD | U14: 10018541 | V14: MAKITA TCT SAWBLADE 165X20X24T A-86038 | W14: =LEN(V14) -> 38
F15: 10013698 | G15: MAKITA POWER PLANER 1911B (4-3/8") 110MM | H15: 15 | K15: 10013721 | L15: MAKITA COMPOUND MITER SAW LS1040 10-1/4" | M15: 15 | P15: =VLOOKUP(R15,'[1]MAKITA MASTERSHEET'!$E:$G,3,0) -> 10018414 | Q15: MAKITA T.C.T SAW BLADE M.STEEL A-83967 | R15: =VLOOKUP(Q15,'[1]MAKITA MASTERSHEET'!$D:$E,2,0) -> A-83967 | S15: MAKITA | T15: =VLOOKUP(R15,'[1]J NEW PRICE'!$A:$B,2,0) -> T.C.T SAW BLADE 185X20X48T THIN M.STEEL | U15: 10018414 | V15: MAKITA SAWBLADE 185MM 48T M.S A-83967 | W15: =LEN(V15) -> 37
F16: 10013704 | G16: MAKITA PLANER 2012NB (304MM) 12" | H16: 4 | K16: 10013727 | L16: MAKITA JIGSAW 4327M (HOLE TYPE) | M16: 28 | P16: =VLOOKUP(R16,'[1]MAKITA MASTERSHEET'!$E:$G,3,0) -> 10036232 | Q16: MAKITA T.C.T SAW BLADE E-12924 | R16: =VLOOKUP(Q16,'[1]MAKITA MASTERSHEET'!$D:$E,2,0) -> E-12924 | S16: MAKITA | T16: =VLOOKUP(R16,'[1]J NEW PRICE'!$A:$B,2,0) -> T.C.T SAW BLADE 185X20X60T METAL EFFICUT | U16: 10036232 | V16: MAKITA SAWBLADE 185MM 60T M EFF E-12924 | W16: =LEN(V16) -> 39
F17: 10013710 | G17: MAKITA CIRCULAR SAW 5103N(335MM) 13-1/8" | H17: 3 | K17: 10017896 | L17: MAKITA DC CLEANER 18V DCL286FRTB | M17: 2 | P17: =VLOOKUP(R17,'[1]MAKITA MASTERSHEET'!$E:$G,3,0) -> 10017967 | Q17: MAKITA T.C.T SAW BLADE 7" S.S B-31697 | R17: =VLOOKUP(Q17,'[1]MAKITA MASTERSHEET'!$D:$E,2,0) -> B-31697 | S17: MAKITA | T17: =VLOOKUP(R17,'[1]J NEW PRICE'!$A:$B,2,0) -> T.C.T SAW BLADE 185X20X64T S.STEEL | U17: 10017967 | V17: MAKITA SAWBLADE 185X20X64T SS B-31697 | W17: =LEN(V17) -> 37
F18: 10013713 | G18: MAKITA CIRCULAR SAW N5900B (235MM)9-1/4" | H18: 10 | K18: 10017898 | L18: MAKITA DC HAMMER DRIVER DRILL DHP487RFJ | M18: 24 | P18: =VLOOKUP(R18,'[1]MAKITA MASTERSHEET'!$E:$G,3,0) -> 10017965 | Q18: MAKITA T.C.T SAW BLADE 7" 60T P-67963 | R18: =VLOOKUP(Q18,'[1]MAKITA MASTERSHEET'!$D:$E,2,0) -> P-67963 | S18: MAKITA | T18: =VLOOKUP(R18,'[1]J NEW PRICE'!$A:$B,2,0) -> T.C.T SAW BLADE 185X20X60T WOOD | U18: 10017965 | V18: MAKITA TCT SAWBLADE 185X20X60T P-67963 | W18: =LEN(V18) -> 38
F19: 10013716 | G19: MAKITA CIRCULAR SAW 5806B (185MM) 7-1/4" | H19: 34 | K19: 10017904 | L19: MAKITA DC CLEANER 40V CL003GZ14 | M19: 9 | P19: =VLOOKUP(R19,'[1]MAKITA MASTERSHEET'!$E:$G,3,0) -> 10018615 | Q19: MAKITA T.C.T SAW BLADE 165X56T B-57364 | R19: =VLOOKUP(Q19,'[1]MAKITA MASTERSHEET'!$D:$E,2,0) -> B-57364 | S19: MAKITA | T19: =VLOOKUP(R19,'[1]J NEW PRICE'!$A:$B,2,0) -> T.C.T SAW BLADE 165X20X56T WOOD EFFICUT | U19: 10018615 | V19: MAKITA TCT SAWBLADE 165MM 56T EF B-57364 | W19: =LEN(V19) -> 40
F20: 10013719 | G20: MAKITA CIRCULAR SAW 5008MG (210MM)8-1/4" | H20: 12 | K20: 10017909 | L20: MAKITA DC HAMMER DRIVER 18V BL DHP489Z | M20: 7 | P20: =VLOOKUP(R20,'[1]MAKITA MASTERSHEET'!$E:$G,3,0) -> 10018527 | Q20: MAKITA JIG SAW BLADE NO.10S A-85824 | R20: =VLOOKUP(Q20,'[1]MAKITA MASTERSHEET'!$D:$E,2,0) -> A-85824 | S20: MAKITA | T20: =VLOOKUP(R20,'[1]J NEW PRICE'!$A:$B,2,0) -> JIG SAW BLADE NO.10S 5PCS/PKG | U20: 10018527 | V20: MAKITA JIG SAWBLADE NO.10S A-85824 HOLE | W20: =LEN(V20) -> 39
F21: 10013721 | G21: MAKITA COMPOUND MITER SAW LS1040 10-1/4" | H21: 5 | K21: 10017927 | L21: MAKITA DC REBAR TYING TOOL 18V DTR181Z | M21: 1 | P21: =VLOOKUP(R21,'[1]MAKITA MASTERSHEET'!$E:$G,3,0) -> 10018526 | Q21: MAKITA JIG SAW BLADE NO. 51 4304 A-86561 | R21: =VLOOKUP(Q21,'[1]MAKITA MASTERSHEET'!$D:$E,2,0) -> A-86561 | S21: MAKITA | T21: =VLOOKUP(R21,'[1]J NEW PRICE'!$A:$B,2,0) -> JIG SAW BLADE NO.51 5PCS/PKG (B-TYPE) | U21: 10018526 | V21: MAKITA JIG SAWBLADE NO.51 A-86561 (PIN) | W21: =LEN(V21) -> 39
F22: 10013727 | G22: MAKITA JIGSAW 4327M (HOLE TYPE) | H22: 32 | K22: 10017936 | L22: MAKITA DC MICROWAVE 40V 8L 500W MW001GZ | M22: 25 | P22: =VLOOKUP(R22,'[1]MAKITA MASTERSHEET'!$E:$G,3,0) -> 10018768 | Q22: MAKITA JIG SAW BLADE B-16 4304 A-85684 | R22: =VLOOKUP(Q22,'[1]MAKITA MASTERSHEET'!$D:$E,2,0) -> A-85684 | S22: MAKITA | T22: =VLOOKUP(R22,'[1]J NEW PRICE'!$A:$B,2,0) -> JIG SAW BLADE B-16 5PCS/PKG | U22: 10018768 | V22: MAKITA JIG SAWBLADE B-16 A-85684 (PIN) | W22: =LEN(V22) -> 38
F23: 10017888 | G23: MAKITA HIGH PER ENGINE OIL 980008606 | H23: 240 | K23: 10017941 | L23: MAKITA DC CHAIN SAW 40V 12" UC003GZ01 | M23: 1 | P23: =VLOOKUP(R23,'[1]MAKITA MASTERSHEET'!$E:$G,3,0) -> 10019397 | Q23: MAKITA JIG SAW BLADE A-86882 | R23: =VLOOKUP(Q23,'[1]MAKITA MASTERSHEET'!$D:$E,2,0) -> A-86882 | S23: MAKITA | T23: =VLOOKUP(R23,'[1]J NEW PRICE'!$A:$B,2,0) -> JIG SAW BLADE NO.1,2,3,8,10S 5PCS/SET | U23: 10019397 | V23: MAKITA JIG SAWBLADE A-86882 (HOLE) | W23: =LEN(V23) -> 34
F24: 10017889 | G24: MAKITA SAW CHAIN 10" SPROCKET 191H08-4 | H24: 4 | K24: 10017943 | L24: MAKITA DC CHAIN SAW 40V 16" UC012GZ | M24: 2 | P24: =VLOOKUP(R24,'[1]MAKITA MASTERSHEET'!$E:$G,3,0) -> 10018529 | Q24: MAKITA T.C.T SAW BLADE WOOD B-62022 | R24: =VLOOKUP(Q24,'[1]MAKITA MASTERSHEET'!$D:$E,2,0) -> B-62022 | S24: MAKITA | T24: =VLOOKUP(R24,'[1]J NEW PRICE'!$A:$B,2,0) -> T.C.T SAW BLADE 185X20X24T WOOD EFFICUT | U24: 10018529 | V24: MAKITA TCT SAWBLADE 185MM 24T EF B-62022 | W24: =LEN(V24) -> 40
... F26: 10017893 | G26: MAKITA SDS-PLUS NEMESIS II E-14532 | H26: 10 | K26: 10017949 | L26: MAKITA DC HEDGE TRIMMER 40V UH014GZ | M26: 5 | P26: =VLOOKUP(R26,'[1]MAKITA MASTERSHEET'!$E:$G,3,0) -> 10051338 | Q26: MAKITA T.C.T SAW BLADE D-81131 | R26: =VLOOKUP(Q26,'[1]MAKITA MASTERSHEET'!$D:$E,2,0) -> D-81131 | S26: MAKITA | T26: =VLOOKUP(R26,'[1]J NEW PRICE'!$A:$B,2,0) -> T.C.T SAW BLADE 136X20X40T MDF | U26: 10051338 | V26: MAKITA TCT SAWBLADE 136X20X40T D-81131 | W26: =LEN(V26) -> 38
F27: 10017894 | G27: MAKITA HAMMER CASE COMPLETE 144787-5 | H27: 6 | K27: 10017953 | L27: MAKITA DC GARDEN SPRAYER 12V 5L US053DZ | M27: 5 | R27: D-65844 | U27: 10018443 | V27: MAKITA ABRASIVEDISC 125 #100 WHT D-65844 | W27: =LEN(V27) -> 40
F28: 10017895 | G28: MAKITA AC VACUUM CLEANER 20L VC2000L | H28: 3 | K28: 10017957 | L28: MAKITA DC VACUUM CLEANER 40V VC008GZ04 | M28: 2 | R28: D-65838 | U28: 10018989 | V28: MAKITA ABRASIVE DISC 125 #80 WHT D-65838 | W28: =LEN(V28) -> 40
F29: 10017896 | G29: MAKITA DC CLEANER 18V DCL286FRTB | H29: 3 | K29: 10017960 | L29: MAKITA DC CIRCULAR SAW 40V 235MM HS009GZ | M29: 2 | R29: D-65872 | U29: 10018935 | V29: MAKITA ABRASIVEDISC 125 #180 WHT D-65872 | W29: =LEN(V29) -> 40
F30: 10017897 | G30: MAKITA DC HAMMER DRIVER DRILL DHP484RFE | H30: 15 | K30: 10017970 | L30: MAKITA PLUNGE CUT SAW 40V 165MM SP001GZ | M30: 2 | R30: B-51437 | U30: 10018230 | V30: MAKITA ABRASIVE DISC 150MM A80 B-51437 | W30: =LEN(V30) -> 38
F31: 10017898 | G31: MAKITA DC HAMMER DRIVER DRILL DHP487RFJ | H31: 11 | K31: 10017984 | L31: MAKITA DC HEDGETRIMMER 40V 650MM UH006GZ | M31: 2 | U31: 10018778 | V31: MAKITA ABRASIVE DISC 125 #240 D-54209 | W31: =LEN(V31) -> 37
F32: 10017899 | G32: MAKITA DC HEDGE TRIMMER 18V DUH507Z | H32: 1 | K32: 10018002 | L32: MAKITA DC DRIVER DRILL 18V BL DDF486Z | M32: 9 | U32: 10018767 | V32: MAKITA ABRASIVE DISC 125 #120 D-54178 | W32: =LEN(V32) -> 37
F33: 10017935 | G33: MAKITA MULTIFUNCTION POW.HEAD 18V DUX18Z | H33: 2 | K33: 10018428 | L33: MAKITA IMPACT DRIVER 18V BL DTD153RTE | M33: 12 | R33: B-51932 | T33: GRINDING WHEEL 150X16X12.7 - GC120H | U33: 10018631 | V33: MAKITA GRINDING WHEEL GB602 GR B-51932 | W33: =LEN(V33) -> 38
F34: 10017936 | G34: MAKITA DC MICROWAVE 40V 8L 500W MW001GZ | H34: 1 | K34: 10018432 | L34: MAKITA IMPACT WRENCH 18V BL DTW300RTJ | M34: 6 | R34: JM23000123 | T34: CARBON BRUSH FOR MT230 | U34: 40007239 | V34: MAKITA CARBON BRUSH CB-500 JM23000123 | W34: =LEN(V34) -> 37
F35: 10017938 | G35: MAKITA DC POLISHER 40V BL 180MM PV001GZ | H35: 5 | K35: 10018440 | L35: MAKITA CLEANER 12V CL106FDSAW | M35: 10 | R35: D-29620 | T35: M FORCE METAL DRILL BIT 2.5X57MM | U35: 40005555 | V35: MAKITA HSS METAL DRILL BIT 2.5MM D-29620 | W35: =LEN(V35) -> 40
F36: 10017941 | G36: MAKITA DC CHAIN SAW 40V 12" UC003GZ01 | H36: 1 | K36: 10018446 | L36: MAKITA DC HAMMER 18V BL 18MM DHR183RTWJ | M36: 5 | R36: D-29692 | T36: M FORCE METAL DRILL BIT 6.0X93MM | U36: 10019574 | V36: MAKITA HSS METAL DRILL BIT 6MM D-29692 | W36: =LEN(V36) -> 38
F37: 10017943 | G37: MAKITA DC CHAIN SAW 40V 16" UC012GZ | H37: 1 | K37: 10018489 | L37: MAKITA DC HAMMER DRIVER DRILL HP002GD201 | M37: 3 | R37: D-29658 | T37: M FORCE METAL DRILL BIT 4.0X75MM | U37: 10019573 | V37: MAKITA HSS METAL DRILL BIT 4MM D-29658 | W37: =LEN(V37) -> 38
F38: 10017945 | G38: MAKITA DC CHAIN SAW 40V 12" UC014GZ | H38: 1 | K38: 10018499 | L38: MAKITA DC ROTARY HAMMER 52MM HR006GZ | M38: 4 | R38: D-29636 | T38: M FORCE METAL DRILL BIT 3.0X61MM | U38: 10019572 | V38: MAKITA HSS METAL DRILL BIT 3MM D-29636 | W38: =LEN(V38) -> 38
F39: 10017947 | G39: MAKITA DC CHAIN SAW 12V BL 100MM UC100DZ | H39: 2 | K39: 10018500 | L39: MAKITA DC CIRCULAR SAW HS003GM201 | M39: 3 | R39: D-29670 | T39: M FORCE METAL DRILL BIT 5.0X86MM | U39: 10018568 | V39: MAKITA HSS METAL DRILL BIT 5MM D-29670 | W39: =LEN(V39) -> 38
F40: 10017948 | G40: MAKITA AC ANGLE GRINDER 180MM GA7070X1 | H40: 3 | K40: 10018507 | L40: MAKITA DC CHAIN SAW 40V UC015GT101 | M40: 1 | R40: D-29614 | T40: M FORCE METAL DRILL BIT 2X49 | U40: 10019268 | V40: MAKITA HSS METAL DRILL BIT 2MM D-29614 | W40: =LEN(V40) -> 38
F41: 10017949 | G41: MAKITA DC HEDGE TRIMMER 40V UH014GZ | H41: 1 | K41: 10018586 | L41: MAKITA HEAT GUN HG6031VK | M41: 14 | R41: =VLOOKUP(U41,'[1]MAKITA MASTERSHEET'!$A:$C,3,0) -> A-86767 | T41: T.C.T SAW BLADE 190X20X60T ALUM | U41: 10019734 | V41: MAKITA TCT SAWBLADE 7" A-86767 ALUM 60T
F42: 10017953 | G42: MAKITA DC GARDEN SPRAYER 12V 5L US053DZ | H42: 1 | K42: 10018593 | L42: MAKITA SLIDE COMPOUND SAW LS1019L | M42: 14 | R42: =VLOOKUP(U42,'[1]MAKITA MASTERSHEET'!$A:$C,3,0) -> B-14607 | T42: T.C.T SAW BLADE 85X15X20T WOOD | U42: 10018277 | V42: MAKITA TCT SAWBLADE 85X15X20T B-14607
...
